# Goxel 0.12.0
# One line per voxel
# X Y Z RRGGBB
1 -3 0 8a0800
0 -2 0 690400
1 -2 0 ae0c0c
2 -2 0 a21008
0 -1 0 000000
1 -1 0 000000
2 -1 0 ae0c0c
0 -3 1 8a0800
1 -3 1 a60800
0 -2 1 ae0c0c
1 -2 1 ae0c0c
0 -1 1 000000
1 -1 1 000000
2 -1 1 c20000
0 -2 2 c20000
0 -1 2 db0808
1 -1 2 c20000
-1 -3 0 8a0800
-2 -2 0 ae0c0c
-1 -2 0 ae0c0c
-2 -1 0 ae0c0c
-1 -1 0 000000
-1 -3 1 a60800
-1 -2 1 ae0c0c
-2 -1 1 ae0c0c
-1 -1 1 000000
-1 -1 2 c20000
-2 0 0 ae0c0c
-1 0 0 ae0c0c
-2 0 1 c20000
-1 0 1 000000
-1 1 1 c20000
-1 0 2 db0808
0 0 0 000000
1 0 0 db0808
2 0 0 c20000
0 1 0 7d0800
0 2 0 311810
0 0 1 db0808
1 0 1 000000
2 0 1 db0808
1 1 1 ff1414
0 0 2 ff1414
1 0 2 db0808
-1 -1 -2 960800
-1 -3 -1 a60800
-1 -2 -1 960800
-2 -1 -1 ae0c0c
-1 -1 -1 000000
0 -2 -2 a21008
0 -1 -2 ae0c0c
1 -1 -2 960800
0 -3 -1 8a0800
1 -3 -1 a21008
0 -2 -1 ae0c0c
1 -2 -1 a21008
0 -1 -1 000000
1 -1 -1 000000
2 -1 -1 ae0c0c
-1 0 -2 a21008
-2 0 -1 ae0c0c
-1 0 -1 000000
-1 1 -1 a21008
0 0 -2 ae0c0c
1 0 -2 ae0c0c
0 0 -1 ae0c0c
1 0 -1 000000
2 0 -1 ae0c0c
1 1 -1 c20000
0 3 -1 3d1c14
