# Goxel 0.12.0
# One line per voxel
# X Y Z RRGGBB
197
0 -2 0 926d31
1 -2 0 a2752d
0 -1 0 ba8e35
1 -1 0 ba8e35
2 -1 0 a67524
0 -2 1 b27d24
1 -2 1 b27d24
0 -1 1 ba8e35
1 -1 1 ba8e35
2 -1 1 b28224
0 -2 2 a2752d
1 -2 2 926d31
0 -1 2 ba8e35
1 -1 2 ba8e35
2 -1 2 a67524
0 -2 3 926d31
1 -2 3 a2752d
0 -1 3 ba8e35
1 -1 3 ba8e35
2 -1 3 a67524
0 -2 4 b27d24
1 -2 4 a67524
0 -1 4 ba8e35
1 -1 4 b27d24
0 -1 5 a67524
-2 -2 0 926d31
-1 -2 0 a2752d
-3 -1 0 a67524
-2 -1 0 ba8e35
-1 -1 0 ba8e35
-2 -2 1 b27d24
-1 -2 1 b27d24
-3 -1 1 b28224
-2 -1 1 ba8e35
-1 -1 1 ba8e35
-2 -2 2 a2752d
-1 -2 2 926d31
-3 -1 2 a67524
-2 -1 2 ba8e35
-1 -1 2 ba8e35
-2 -2 3 926d31
-1 -2 3 a2752d
-3 -1 3 a67524
-2 -1 3 ba8e35
-1 -1 3 ba8e35
-2 -2 4 a67524
-1 -2 4 b27d24
-2 -1 4 b28224
-1 -1 4 ba8e35
-1 -1 5 a67524
-3 0 0 c2963d
-2 0 0 ba8e35
-1 0 0 ba8e35
-2 1 0 e3ba65
-1 1 0 dba641
-3 0 1 ba8e35
-2 0 1 ba8e35
-1 0 1 ba8e35
-2 1 1 ce9e39
-1 1 1 e3ba65
-3 0 2 c2963d
-2 0 2 ba8e35
-1 0 2 ba8e35
-2 1 2 e3ba65
-1 1 2 c2963d
-3 0 3 b68a28
-2 0 3 ba8e35
-1 0 3 ba8e35
-2 1 3 be9639
-1 1 3 b68a28
-2 0 4 b28224
-1 0 4 ba8e35
-1 1 4 b28224
-1 0 5 b27d24
0 0 0 ba8e35
1 0 0 ba8e35
2 0 0 c2963d
0 1 0 ce9e39
1 1 0 e3ba65
0 0 1 ba8e35
1 0 1 ba8e35
2 0 1 ba8e35
0 1 1 e3ba65
1 1 1 c2963d
0 0 2 ba8e35
1 0 2 ba8e35
2 0 2 b68a28
0 1 2 ba8e35
1 1 2 ba8e35
0 0 3 ba8e35
1 0 3 ba8e35
2 0 3 b68a28
0 1 3 b68a28
1 1 3 b28224
0 0 4 ba8e35
1 0 4 b28224
0 1 4 b28224
0 0 5 b27d24
-1 -2 -6 b6963d
-1 -1 -6 d7b259
-2 -2 -5 a6863d
-1 -2 -5 b27d24
-3 -1 -5 b69a51
-2 -1 -5 d7b259
-1 -1 -5 e3ba65
-2 -2 -4 a2752d
-1 -2 -4 926d31
-3 -1 -4 a67524
-2 -1 -4 efc669
-1 -1 -4 e3ba65
-2 -2 -3 926d31
-1 -2 -3 a2752d
-3 -1 -3 a67524
-2 -1 -3 ba8e35
-1 -1 -3 ba8e35
-2 -2 -2 b27d24
-1 -2 -2 b27d24
-3 -1 -2 b28224
-2 -1 -2 ba8e35
-1 -1 -2 ba8e35
-2 -2 -1 a2752d
-1 -2 -1 926d31
-3 -1 -1 a67524
-2 -1 -1 ba8e35
-1 -1 -1 ba8e35
0 -2 -6 a6863d
1 -2 -6 a2752d
0 -1 -6 efc669
1 -1 -6 d7b259
0 -2 -5 b27d24
1 -2 -5 b27d24
0 -1 -5 e3ba65
1 -1 -5 ba8e35
2 -1 -5 b6963d
0 -2 -4 a2752d
1 -2 -4 926d31
0 -1 -4 ba8e35
1 -1 -4 ba8e35
2 -1 -4 a6863d
0 -2 -3 926d31
1 -2 -3 a2752d
0 -1 -3 ba8e35
1 -1 -3 ba8e35
2 -1 -3 a67524
0 -2 -2 b27d24
1 -2 -2 b27d24
0 -1 -2 ba8e35
1 -1 -2 ba8e35
2 -1 -2 b28224
0 -2 -1 a2752d
1 -2 -1 926d31
0 -1 -1 ba8e35
1 -1 -1 ba8e35
2 -1 -1 a67524
-1 0 -5 efc669
-3 0 -4 e3ba65
-1 0 -4 efc669
-1 1 -4 e3be65
-3 0 -3 ba8e35
-2 0 -3 e3ba65
-1 0 -3 e3ba65
-2 1 -3 d7b259
-1 1 -3 d7b259
-3 0 -2 c2963d
-2 0 -2 ba8e35
-1 0 -2 ba8e35
-2 1 -2 d2aa59
-1 1 -2 ce9e39
-3 0 -1 ba8e35
-2 0 -1 ba8e35
-1 0 -1 ba8e35
-2 1 -1 c2963d
-1 1 -1 e3ba65
0 0 -5 e3be65
1 0 -5 efc669
2 0 -5 e3ba65
1 1 -5 d7b259
0 0 -4 e3ba65
1 0 -4 ba8e35
2 0 -4 c2963d
0 1 -4 d7b259
1 1 -4 d2aa59
0 0 -3 ba8e35
1 0 -3 ba8e35
2 0 -3 ba8e35
0 1 -3 d2aa59
1 1 -3 c2963d
0 0 -2 ba8e35
1 0 -2 ba8e35
2 0 -2 c2963d
0 1 -2 dba641
1 1 -2 e3ba65
0 0 -1 ba8e35
1 0 -1 ba8e35
2 0 -1 ba8e35
0 1 -1 e3ba65
1 1 -1 c2963d
