# Goxel 0.12.0
# One line per voxel
# X Y Z RRGGBB
81
-1 -1 0 455510
-1 -1 2 39490c
-1 -1 3 455510
-1 -1 4 3d3120
0 -1 0 39490c
0 -1 1 455510
1 -1 1 455510
0 -1 2 39490c
1 -1 2 556d14
0 -1 3 313d08
1 -1 3 455510
0 -1 4 4d3d28
1 -1 4 4d3d28
-1 0 0 556d14
-1 1 0 4d6110
-1 0 1 39490c
-1 0 2 455510
-1 1 2 4d6110
-1 0 3 39490c
-1 1 3 455510
-2 0 4 4d6110
-1 0 4 455510
0 0 0 040404
1 0 0 455510
0 1 0 597518
1 1 0 39490c
0 0 1 040404
1 0 1 556d14
0 1 1 455510
1 1 1 455510
0 0 2 040404
1 0 2 617d1c
0 1 2 4d6110
1 1 2 556d14
0 0 3 040404
1 0 3 556d14
0 1 3 556d14
1 1 3 597518
0 0 4 55412d
1 0 4 4d6110
0 1 4 39490c
1 1 4 455510
-2 0 -4 452418
-1 0 -4 2d1810
-2 1 -4 452418
-1 1 -4 4d281c
-2 0 -3 4d6110
-1 0 -3 040404
-2 1 -3 455510
-1 1 -3 597518
-2 0 -2 393910
-1 0 -2 452418
-1 1 -2 4d281c
-2 0 -1 455510
-1 0 -1 455510
-1 1 -1 39490c
0 0 -4 2d1810
1 0 -4 2d1810
2 0 -4 452418
0 1 -4 452418
1 1 -4 452418
2 1 -4 4d281c
0 0 -3 040404
1 0 -3 393910
2 0 -3 556d14
0 1 -3 597518
1 1 -3 455510
2 1 -3 597518
0 0 -2 452418
0 1 -2 4d281c
0 0 -1 455510
1 0 -1 556d14
0 1 -1 455510
-1 -1 -4 4d281c
-1 -1 -3 39490c
0 -1 -4 452418
1 -1 -4 452418
2 -1 -4 4d281c
0 -1 -3 313d08
1 -1 -3 455510
2 -1 -3 617d1c