# Goxel 0.12.0
# One line per voxel
# X Y Z RRGGBB
182
-1 -5 0 597518
-1 -4 0 556d14
-1 -3 0 4d6110
-2 -2 0 556d14
-1 -2 0 4d3118
-3 -1 0 597518
-2 -1 0 4d3118
-1 -1 0 ae7d55
-2 -2 1 597518
-1 -2 1 556d14
-3 -1 1 617d1c
-2 -1 1 4d3118
-1 -1 1 ae7d55
-1 -2 2 597518
-2 -1 2 617d1c
-1 -1 2 ae7d55
-1 -1 3 597518
0 -2 0 455510
1 -2 0 ffaa00
0 -1 0 ae7d55
1 -1 0 ff7900
0 -2 1 556d14
1 -2 1 597518
2 -2 1 617d1c
0 -1 1 ae7d55
1 -1 1 55391c
2 -1 1 698a20
0 -2 2 556d14
1 -2 2 556d14
0 -1 2 ae7d55
1 -1 2 4d6110
0 -1 3 556d14
-3 0 0 597518
-2 0 0 4d3118
-1 0 0 d2a682
-3 1 0 597518
-2 1 0 4d3118
-1 1 0 ae7d55
-2 2 0 556d14
-1 2 0 4d3118
-1 3 0 4d6110
-1 4 0 556d14
-1 5 0 597518
-3 0 1 617d1c
-2 0 1 4d3118
-1 0 1 d2a682
-3 1 1 617d1c
-2 1 1 4d3118
-1 1 1 ae7d55
-2 2 1 597518
-1 2 1 556d14
-2 0 2 698a20
-1 0 2 d2a682
-2 1 2 617d1c
-1 1 2 ae7d55
-1 2 2 597518
-1 0 3 617d1c
-1 1 3 597518
0 0 0 d2a682
1 0 0 be926d
2 0 0 556d14
0 1 0 ae7d55
1 1 0 ffaa00
0 2 0 4d6110
1 2 0 ff7900
0 0 1 d2a682
1 0 1 597518
0 1 1 ae7d55
1 1 1 55391c
2 1 1 698a20
0 2 1 556d14
1 2 1 597518
2 2 1 617d1c
0 0 2 d2a682
1 0 2 be926d
2 0 2 556d14
0 1 2 ae7d55
1 1 2 4d6110
0 2 2 556d14
1 2 2 556d14
0 0 3 597518
1 0 3 597518
0 1 3 556d14
-2 -1 -4 1c2010
-1 -1 -4 313d10
-2 -2 -3 313d10
-1 -2 -3 4d6110
-2 -1 -3 1c2010
-1 -1 -3 ae7d55
-1 -3 -2 556d14
-2 -2 -2 3d4d14
-1 -2 -2 597518
-2 -1 -2 243110
-1 -1 -2 ae7d55
-1 -4 -1 4d6110
-1 -3 -1 455510
-2 -2 -1 4d6110
-1 -2 -1 4d3118
-3 -1 -1 3d4d14
-2 -1 -1 4d3118
-1 -1 -1 ae7d55
0 -1 -4 455510
1 -1 -4 556d14
0 -2 -3 4d6110
1 -2 -3 4d6110
0 -1 -3 ae7d55
1 -1 -3 55391c
2 -1 -3 617d1c
0 -2 -2 455510
1 -2 -2 556d14
0 -1 -2 ae7d55
1 -1 -2 55391c
2 -1 -2 597518
0 -2 -1 597518
1 -2 -1 597518
2 -2 -1 617d1c
0 -1 -1 ae7d55
1 -1 -1 55391c
2 -1 -1 556d14
-4 0 -4 1c2010
-3 0 -4 1c2010
-2 0 -4 313d10
-1 0 -4 313d10
-2 1 -4 1c2010
-1 1 -4 313d10
-3 0 -3 41392d
-2 0 -3 597518
-1 0 -3 d2a682
-2 1 -3 1c2010
-1 1 -3 ae7d55
-2 2 -3 313d10
-1 2 -3 4d6110
-3 0 -2 1c2010
-2 0 -2 4d3118
-1 0 -2 d2a682
-2 1 -2 243110
-1 1 -2 ae7d55
-2 2 -2 3d4d14
-1 2 -2 597518
-1 3 -2 556d14
-3 0 -1 243110
-2 0 -1 4d3118
-1 0 -1 d2a682
-3 1 -1 3d4d14
-2 1 -1 4d3118
-1 1 -1 ae7d55
-2 2 -1 4d6110
-1 2 -1 4d3118
-1 3 -1 455510
-1 4 -1 4d6110
0 0 -4 455510
1 0 -4 597518
2 0 -4 617d1c
0 1 -4 455510
1 1 -4 556d14
0 0 -3 d2a682
1 0 -3 be926d
2 0 -3 698a20
0 1 -3 ae7d55
1 1 -3 55391c
2 1 -3 617d1c
0 2 -3 4d6110
1 2 -3 4d6110
0 0 -2 d2a682
1 0 -2 be926d
2 0 -2 4d6110
0 1 -2 ae7d55
1 1 -2 55391c
2 1 -2 597518
0 2 -2 4d6110
1 2 -2 556d14
0 0 -1 d2a682
1 0 -1 be926d
2 0 -1 55391c
3 0 -1 617d1c
4 0 -1 698a20
0 1 -1 ae7d55
1 1 -1 55391c
2 1 -1 556d14
0 2 -1 597518
1 2 -1 597518
2 2 -1 617d1c
