# Goxel 0.12.0
# One line per voxel
# X Y Z RRGGBB
359
-2 -3 0 313d08
-1 -3 0 313d08
-3 -2 0 39490c
-2 -2 0 d2a682
-1 -2 0 040404
-3 -1 0 39490c
-2 -1 0 d2a682
-1 -1 0 040404
-1 -4 1 39490c
-3 -3 1 39490c
-2 -3 1 313d08
-1 -3 1 040404
-3 -2 1 455510
-2 -2 1 d2a682
-1 -2 1 040404
-3 -1 1 455510
-2 -1 1 d2a682
-1 -1 1 040404
-1 -5 2 556d14
-2 -4 2 455510
-1 -4 2 040404
-3 -3 2 4d6110
-2 -3 2 d2a682
-1 -3 2 040404
-3 -2 2 556d14
-2 -2 2 d2a682
-1 -2 2 040404
-3 -1 2 4d6110
-2 -1 2 d2a682
-1 -1 2 040404
-1 -5 3 556d14
-2 -4 3 4d6110
-1 -4 3 040404
-2 -3 3 556d14
-1 -3 3 040404
-3 -2 3 556d14
-2 -2 3 d2a682
-1 -2 3 040404
-3 -1 3 4d6110
-2 -1 3 d2a682
-1 -1 3 040404
-1 -4 4 556d14
-1 -3 4 4d6110
-2 -2 4 4d6110
-1 -2 4 455510
-2 -1 4 455510
-1 -1 4 d2a682
-2 -1 5 313d08
-1 -1 5 455510
0 -3 0 313d08
1 -3 0 4d6110
0 -2 0 040404
1 -2 0 5d4931
2 -2 0 597518
0 -1 0 040404
1 -1 0 5d4931
2 -1 0 4d6110
0 -4 1 39490c
0 -3 1 040404
1 -3 1 39490c
2 -3 1 39490c
0 -2 1 040404
1 -2 1 55412d
2 -2 1 455510
0 -1 1 040404
1 -1 1 5d4931
2 -1 1 39490c
0 -5 2 597518
1 -5 2 556d14
0 -4 2 040404
1 -4 2 39490c
2 -4 2 455510
0 -3 2 040404
1 -3 2 5d4931
2 -3 2 4d6110
0 -2 2 040404
1 -2 2 5d4931
2 -2 2 597518
0 -1 2 040404
1 -1 2 5d4931
2 -1 2 556d14
0 -5 3 597518
0 -4 3 040404
1 -4 3 556d14
0 -3 3 040404
1 -3 3 455510
2 -3 3 597518
0 -2 3 040404
1 -2 3 5d4931
2 -2 3 617d1c
0 -1 3 040404
1 -1 3 5d4931
2 -1 3 556d14
0 -4 4 556d14
0 -3 4 455510
0 -2 4 455510
1 -2 4 39490c
0 -1 4 d2a682
1 -1 4 455510
0 -1 5 455510
-2 0 0 313d08
-1 0 0 040404
-3 1 0 39490c
-2 1 0 d2a682
-1 1 0 040404
-3 2 0 39490c
-2 2 0 d2a682
-1 2 0 040404
-2 3 0 313d08
-1 3 0 313d08
-2 0 1 39490c
-1 0 1 040404
-3 1 1 455510
-2 1 1 d2a682
-1 1 1 040404
-3 2 1 455510
-2 2 1 d2a682
-1 2 1 040404
-3 3 1 39490c
-2 3 1 313d08
-1 3 1 040404
-1 4 1 39490c
-2 0 2 455510
-1 0 2 040404
-3 1 2 4d6110
-2 1 2 d2a682
-1 1 2 040404
-3 2 2 556d14
-2 2 2 d2a682
-1 2 2 040404
-3 3 2 4d6110
-2 3 2 d2a682
-1 3 2 040404
-2 4 2 455510
-1 4 2 040404
-1 5 2 455510
-2 0 3 4d6110
-1 0 3 040404
-3 1 3 556d14
-2 1 3 d2a682
-1 1 3 040404
-3 2 3 556d14
-2 2 3 d2a682
-1 2 3 040404
-2 3 3 556d14
-1 3 3 040404
-2 4 3 4d6110
-1 4 3 040404
-1 5 3 556d14
-2 0 4 39490c
-1 0 4 d2a682
-2 1 4 455510
-1 1 4 d2a682
-2 2 4 4d6110
-1 2 4 455510
-1 3 4 4d6110
-1 4 4 556d14
-2 0 5 455510
-1 0 5 597518
-2 1 5 313d08
-1 1 5 313d08
0 0 0 040404
1 0 0 597518
2 0 0 597518
0 1 0 040404
1 1 0 5d4931
2 1 0 4d6110
0 2 0 040404
1 2 0 5d4931
2 2 0 597518
0 3 0 313d08
1 3 0 4d6110
0 0 1 040404
1 0 1 597518
2 0 1 4d6110
0 1 1 040404
1 1 1 5d4931
2 1 1 39490c
0 2 1 040404
1 2 1 55412d
2 2 1 455510
0 3 1 040404
1 3 1 39490c
2 3 1 39490c
0 4 1 313d08
0 0 2 040404
1 0 2 597518
2 0 2 455510
0 1 2 040404
1 1 2 5d4931
2 1 2 556d14
0 2 2 040404
1 2 2 55412d
2 2 2 597518
0 3 2 040404
1 3 2 5d4931
2 3 2 4d6110
0 4 2 040404
1 4 2 39490c
2 4 2 455510
0 5 2 597518
1 5 2 4d6110
0 0 3 040404
1 0 3 4d6110
0 1 3 040404
1 1 3 5d4931
2 1 3 556d14
0 2 3 040404
1 2 3 5d4931
2 2 3 617d1c
0 3 3 040404
1 3 3 455510
2 3 3 597518
0 4 3 040404
1 4 3 556d14
0 5 3 597518
0 0 4 d2a682
1 0 4 39490c
0 1 4 d2a682
1 1 4 455510
0 2 4 455510
1 2 4 39490c
0 3 4 455510
0 4 4 556d14
0 0 5 597518
0 1 5 455510
-2 -1 -5 597518
-1 -1 -5 4d3d28
-1 -3 -4 452818
-2 -2 -4 4d3118
-1 -2 -4 4d3118
-2 -1 -4 51351c
-1 -1 -4 040404
-1 -3 -3 5d4931
-2 -2 -3 5d4931
-1 -2 -3 040404
-2 -1 -3 5d4931
-1 -1 -3 040404
-1 -3 -2 39490c
-2 -2 -2 455510
-1 -2 -2 040404
-2 -1 -2 4d6110
-1 -1 -2 040404
-2 -3 -1 39490c
-1 -3 -1 455510
-2 -2 -1 455510
-1 -2 -1 040404
-2 -1 -1 455510
-1 -1 -1 040404
0 -1 -5 4d3d28
1 -1 -5 61452d
0 -3 -4 452818
1 -3 -4 4d3118
0 -2 -4 4d3118
1 -2 -4 4d3118
2 -2 -4 51351c
0 -1 -4 040404
1 -1 -4 453524
2 -1 -4 694528
0 -3 -3 5d4931
1 -3 -3 4d3d28
0 -2 -3 040404
1 -2 -3 55412d
2 -2 -3 61452d
0 -1 -3 040404
1 -1 -3 55412d
2 -1 -3 694d35
0 -3 -2 4d6110
1 -3 -2 4d6110
0 -2 -2 040404
1 -2 -2 455510
0 -1 -2 040404
1 -1 -2 d2a682
2 -1 -2 597518
0 -3 -1 39490c
1 -3 -1 455510
0 -2 -1 040404
1 -2 -1 4d6110
0 -1 -1 040404
1 -1 -1 ca9a71
2 -1 -1 597518
-1 0 -5 51351c
-2 1 -5 597518
-1 1 -5 4d3d28
-2 0 -4 452818
-1 0 -4 040404
-2 1 -4 51351c
-1 1 -4 040404
-2 2 -4 4d3118
-1 2 -4 4d3118
-1 3 -4 452818
-2 0 -3 393910
-1 0 -3 040404
-2 1 -3 5d4931
-1 1 -3 040404
-2 2 -3 5d4931
-1 2 -3 040404
-1 3 -3 5d4931
-1 0 -2 39490c
-2 1 -2 4d6110
-1 1 -2 040404
-2 2 -2 455510
-1 2 -2 040404
-1 3 -2 39490c
-1 0 -1 313d08
-2 1 -1 455510
-1 1 -1 040404
-2 2 -1 455510
-1 2 -1 040404
-2 3 -1 39490c
-1 3 -1 455510
0 0 -5 4d3d28
1 0 -5 4d3d28
2 0 -5 694d35
0 1 -5 4d3d28
1 1 -5 61452d
0 0 -4 040404
1 0 -4 3d3120
2 0 -4 754d31
0 1 -4 040404
1 1 -4 453524
2 1 -4 694528
0 2 -4 4d3118
1 2 -4 4d3118
2 2 -4 51351c
0 3 -4 452818
1 3 -4 4d3118
0 0 -3 040404
1 0 -3 55412d
2 0 -3 694d35
0 1 -3 040404
1 1 -3 55412d
2 1 -3 694d35
0 2 -3 040404
1 2 -3 5d4931
2 2 -3 61452d
0 3 -3 5d4931
1 3 -3 55412d
0 0 -2 040404
1 0 -2 d2a682
2 0 -2 455510
0 1 -2 040404
1 1 -2 d2a682
2 1 -2 597518
0 2 -2 040404
1 2 -2 455510
0 3 -2 4d6110
1 3 -2 4d6110
0 0 -1 040404
1 0 -1 597518
2 0 -1 4d6110
0 1 -1 040404
1 1 -1 ca9a71
2 1 -1 597518
0 2 -1 040404
1 2 -1 4d6110
0 3 -1 39490c
1 3 -1 455510
